Workbook

Sheet 說明
A1: 英語補習班名錄
A2: 楊梅永平路 20 公里圈 ＋ 全台立案英文補習班
A4: 擷取日期 | B4: 2026-09-09（Google 名單）／2026-09-10（立案資料與 email）
A6: 分頁說明
A7: 楊梅20km名錄 | B7: 159 家。以桃園市楊梅區永平路（24.920261, 121.178141）為圓心、半徑 20 公里的英文補習班。名單來自 Google Maps，含評分、官網、座標與距離；其中 120 家已對上立案資料。
A8: 全台英文補習班 | B8: 4,685 家。完全來自教育部立案資料，涵蓋全台 22 縣市。沒有 Google 評分、官網、座標與距離——那些需要 Places API，而免費配額每日僅 100 次，不可能涵蓋數千家。
A9: 規模統計 | B9: 整體、依距離級距、依規模分級、依行政區、全台依縣市。全部為公式，會自動重算。
A10: 未對上立案 | B10: 39 家 Google 找得到、但對不上立案資料者。
A12: 資料來源
A13: 名單／聯絡方式 | B13: Google Maps Places API (New) places:searchNearby。六角網格 85 格覆蓋 20 公里圓域，每格半徑 2,800 公尺；類型限 school 與 child_care_agency，排除主類型為公立中小學與大學者。
A14: 立案資料／email／規模 | B14: 教育部「直轄市及各縣市短期補習班資訊管理系統」，經 https://afterschools.olc.tw/ 取得。全台 17,836 家立案補習班中，外語類 4,819 家，篩出實際教英文且未廢止者 4,685 家。
A15: 官方原始站 | B15: https://bsb.kh.edu.tw/ 立案資料權威版本，鏡站為二手；有出入以官方為準。
A17: email 欄位
A18: 來源 | B18: 立案登記的聯絡信箱，非 Google 資料（Google Places 沒有 email 欄位）。
A19: 覆蓋率 | B19: 楊梅名錄 113/159 家；全台 3,790/4,685 家（80%）。全台其中 2,140 家是 Gmail。空白代表立案時未填或未更新。
A20: 注意 | B20: 這是負責人或班務的登記信箱，未必是招生窗口，也可能已停用。群發前請先小量測試退信率，並遵守個資法與商業電子郵件相關規範。
A22: 重要限制
A23: 沒有學生人數 | B23: 實際在學人數不屬於公開資訊，兩個來源都沒有這個欄位。
A24: 核定容量的算法 | B24: 各核准科目「班級數 × 每班核准人數」加總，同一批學生修多科會重複計算，會出現「4 間教室卻核定 1,773 人」。判斷規模請看教室數與班舍總面積。
A25: 楊梅名單不完整 | B25: Places API 單次上限 20 筆，85 格中有 36 格觸頂，中壢、桃園、八德等密集區有遺漏。同範圍立案外語類實有 1,064 家，遠多於 Google 能看到的 159 家。
A26: 全台名單較完整但無距離 | B26: 立案資料是普查等級，但沒有經緯度。要算距離需 Geocoding API。
A27: 英文判定方式 | B27: 全台分頁以「核准科目含英文或美語」為準，其次看名稱；純日語、韓語補習班已剔除，已廢止／註銷者亦剔除。
A29: 規模分級標準
A30: 大型 | B30: 班舍總面積 ≥ 400 ㎡ 或教室 ≥ 8 間
A31: 中型 | B31: ≥ 200 ㎡ 或 ≥ 5 間
A32: 小型 | B32: 其餘
A33: 空白 | B33: 未對上立案資料，無規模數據

Sheet 楊梅20km名錄
A1: 距離級距 | B1: 距離(km) | C1: 名稱（Google 招牌） | D1: 立案名稱 | E1: 縣市 | F1: 行政區 | G1: 地址 | H1: 電話 | I1: Email | J1: 官網 | K1: 評分 | L1: 評論數 | M1: 規模 | N1: 教室數 | O1: 教室面積(㎡) | P1: 班舍總面積(㎡) | Q1: 核准班級數 | R1: 登記師資(人) | S1: 核定容量(人) | T1: 英文科核定(人) | U1: 立案類別 | V1: 立案日期 | W1: 負責人 | X1: 班主任 | Y1: 比對方式 | Z1: 立案頁 | AA1: Google Maps | AB1: 緯度 | AC1: 經度
A2: 0–5 km | B2: 0.74 | C2: D&V Art and English Academy 英語藝術學院 | D2: 私立大衛與費雯莉英語短期補習班 | E2: 桃園市 | F2: 楊梅區 | G2: 桃園市楊梅區四維里四維路62號 | H2: 03 481 0548 | I2: dvenglish2021@gmail.com | K2: 5 | L2: 2 | M2: 中型 | N2: 3 | O2: 73.08 | P2: 210.65 | Q2: 3 | R2: 1 | S2: 198 | T2: 198 | U2: 外語類 | V2: 2008-07-01 | W2: 鄧泓敦 | X2: 江筱書 | Y2: address | Z2: 立案頁 | AA2: 地圖 | AB2: 24.913928 | AC2: 121.18044
A3: 0–5 km | B3: 0.75 | C3: 私立勝豐美語珠心算短期補習班 | D3: 私立勝豐美語珠心算短期補習班 | E3: 桃園市 | F3: 楊梅區 | G3: 桃園市楊梅區埔心里新興街35號 | H3: 03 481 7643 | I3: li996110@gmail.com | J3: 官網 | K3: 5 | L3: 12 | M3: 小型 | N3: 3 | O3: 76.43 | P3: 144.07 | Q3: 3 | R3: 2 | S3: 45 | T3: 30 | U3: 外語類,商類：珠算、心算、會計 | V3: 2002-02-20 | W3: 葉至芹 | X3: 黎桂容 | Y3: address | Z3: 立案頁 | AA3: 地圖 | AB3: 24.918406 | AC3: 121.18533
A4: 0–5 km | B4: 0.89 | C4: 空中美語兒童美語 楊梅艾奇德 分校 | E4: 桃園市 | F4: 楊梅區 | G4: 桃園市楊梅區四維里文化街96號 | H4: 03 481 8811 | J4: 官網 | K4: 5 | L4: 1 | AA4: 地圖 | AB4: 24.914552 | AC4: 121.18428
A5: 0–5 km | B5: 0.96 | C5: 承恩美語補習班 | D5: 環愛國際教育管理顧問股份有限公司附設私立承恩語文數學短期補習班 | E5: 桃園市 | F5: 楊梅區 | G5: 桃園市楊梅區四維里四維路162號 | H5: 03 481 1177 | I5: pipi_5016@yahoo.com.tw | K5: 4.8 | L5: 33 | M5: 中型 | N5: 6 | O5: 190.82 | P5: 282.26 | Q5: 6 | R5: 4 | S5: 156 | T5: 54 | U5: 外語類 | V5: 2004-12-16 | W5: 陳和順 | X5: 陳雪芳 | Y5: phone | Z5: 立案頁 | AA5: 地圖 | AB5: 24.912301 | AC5: 121.18172
A6: 0–5 km | B6: 3.03 | C6: 甜蜜美語文理短期補習班 | E6: 桃園市 | F6: 楊梅區 | G6: 桃園市楊梅區裕成里裕成路158巷31號 | H6: 03 431 4018 | K6: 3 | L6: 2 | AA6: 地圖 | AB6: 24.898957 | AC6: 121.15943
A7: 0–5 km | B7: 3.3 | C7: 愛美語楊梅大同二校-漢峰補習班 | D7: 私立漢峰文理短期補習班梅高分班 | E7: 桃園市 | F7: 楊梅區 | G7: 桃園市楊梅區楊梅里梅高路60號 | H7: 03 488 2055 | I7: melody_cher@yahoo.com.tw | K7: 5 | L7: 2 | M7: 小型 | N7: 4 | O7: 111.3 | P7: 182.51 | Q7: 14 | R7: 6 | S7: 340 | T7: 106 | U7: 文理類,外語類 | V7: 2025-12-24 | W7: 謝鳳璇 | X7: 歐馥瑄 | Y7: address | Z7: 立案頁 | AA7: 地圖 | AB7: 24.91729 | AC7: 121.14555
A8: 0–5 km | B8: 3.35 | C8: 莫比思美語楊梅分校 智瀚語文補習班 | D8: 私立智瀚語文短期補習班 | E8: 桃園市 | F8: 楊梅區 | G8: 桃園市楊梅區楊梅里大平街23號 | H8: 03 478 3105 | I8: april.chen1977@gmail.com | K8: 4.8 | L8: 4 | M8: 小型 | N8: 4 | O8: 88.19 | P8: 190.76 | Q8: 4 | R8: 4 | S8: 71 | T8: 46 | U8: 外語類 | V8: 2012-06-04 | W8: 陳宗婷 | X8: 陳宗婷 | Y8: address | Z8: 立案頁 | AA8: 地圖 | AB8: 24.910713 | AC8: 121.14667
A9: 0–5 km | B9: 3.37 | C9: 愛美語楊梅大同一校-漢峰語文文理補習班 | D9: 私立漢峰語文文理短期補習班 | E9: 桃園市 | F9: 楊梅區 | G9: 桃園市楊梅區楊梅里大平街62號 | H9: 03 475 0803 | I9: melody_cher@yahoo.com.tw | J9: 官網 | K9: 5 | L9: 21 | M9: 中型 | N9: 4 | O9: 58.42 | P9: 221.04 | Q9: 12 | R9: 8 | S9: 120 | T9: 56 | U9: 文理類,外語類 | V9: 2003-08-19 | W9: 謝鳳璇 | X9: 謝鳳璇 | Y9: address | Z9: 立案頁 | AA9: 地圖 | AB9: 24.910871 | AC9: 121.1464
A10: 0–5 km | B10: 3.48 | C10: 私立傑西美語短期補習班-楊梅兒童美語|推薦英文班|英文補習班|全美班|外師一對一|全民英檢課程|全科補習班|幼兒美語 | D10: 私立傑西魔法美語文理短期補習班 | E10: 桃園市 | F10: 楊梅區 | G10: 桃園市楊梅區楊梅里大模街33號57號 | H10: 03 478 0758 | I10: jessiemagicschool@gmail.com | J10: 官網 | K10: 4.9 | L10: 104 | M10: 中型 | N10: 5 | O10: 81.39 | P10: 143.94 | Q10: 14 | R10: 11 | S10: 176 | T10: 104 | U10: 外語類 | V10: 2002-10-11 | W10: 廖月華 | X10: 張秀蘭 | Y10: address | Z10: 立案頁 | AA10: 地圖 | AB10: 24.911836 | AC10: 121.14487
A11: 0–5 km | B11: 3.48 | C11: 政大聯合文理語文短期補習班 | D11: 私立傑兒文理短期補習班 | E11: 桃園市 | F11: 楊梅區 | G11: 桃園市楊梅區楊梅里大成路109號3F | H11: 0981 745 350 | I11: qaz62062009@gmail.com | K11: 1 | L11: 1 | M11: 小型 | N11: 4 | O11: 128.13 | P11: 185.33 | Q11: 5 | R11: 1 | S11: 118 | T11: 20 | U11: 文理類,外語類 | V11: 2009-06-23 | W11: 張瑞智 | X11: 張瑞智 | Y11: address | Z11: 立案頁 | AA11: 地圖 | AB11: 24.910428 | AC11: 121.14539
A12: 0–5 km | B12: 3.56 | C12: 喬立安美語Joanne’s Language Program | D12: 私立喬立安美語短期補習班 | E12: 桃園市 | F12: 楊梅區 | G12: 桃園市楊梅區楊江里大平街85號 | H12: 03 485 4477 | I12: angelahsieh@qq.com | J12: 官網 | K12: 4.6 | L12: 10 | M12: 小型 | N12: 1 | O12: 38.25 | P12: 120.5 | Q12: 2 | R12: 4 | S12: 68 | T12: 68 | U12: 外語類 | V12: 2008-06-04 | W12: 謝幼珍 | X12: 謝幼珍 | Y12: address | Z12: 立案頁 | AA12: 地圖 | AB12: 24.910933 | AC12: 121.1444
A13: 0–5 km | B13: 3.61 | C13: 空中美語兒童美語 佶林文理短期補習班 | D13: 私立佶林文理短期補習班 | E13: 桃園市 | F13: 楊梅區 | G13: 桃園市楊梅區楊江里大平街126號 | H13: 03 485 4778 | I13: m875205@yahoo.com.tw | K13: 4.4 | L13: 19 | M13: 小型 | N13: 3 | O13: 39.98 | P13: 107.7 | Q13: 12 | R13: 8 | S13: 122 | T13: 30 | U13: 外語類 | V13: 2004-05-25 | W13: 黃瓅靚 | X13: 黃瓅靚 | Y13: address | Z13: 立案頁 | AA13: 地圖 | AB13: 24.911095 | AC13: 121.14381
A14: 0–5 km | B14: 3.66 | C14: 凱思英語短期補習班 | D14: 私立凱思英語文理短期補習班 | E14: 桃園市 | F14: 楊梅區 | G14: 桃園市楊梅區永寧里永寧路一巷6號 | H14: 03 485 4650 | I14: ksenglish05@gmail.com | J14: 官網 | K14: 4.3 | L14: 24 | M14: 小型 | N14: 3 | O14: 31 | P14: 77.73 | Q14: 26 | R14: 10 | S14: 216 | T14: 75 | U14: 外語類 | V14: 2014-12-29 | W14: 王敏而 | X14: 明道增 | Y14: phone | Z14: 立案頁 | AA14: 地圖 | AB14: 24.903164 | AC14: 121.14711
A15: 0–5 km | B15: 3.68 | C15: 群勵文理美語補習班 | D15: 私立群勵文理美語短期補習班 | E15: 桃園市 | F15: 楊梅區 | G15: 桃園市楊梅區永寧里永寧路17巷2號 | H15: 03 488 0637 | K15: 5 | L15: 5 | M15: 小型 | N15: 2 | O15: 41.02 | P15: 72.75 | Q15: 5 | R15: 3 | S15: 72 | T15: 30 | U15: 文理類,外語類 | V15: 2007-01-08 | W15: 曾倩敏 | X15: 曾倩敏 | Y15: address | Z15: 立案頁 | AA15: 地圖 | AB15: 24.903122 | AC15: 121.14698
A16: 0–5 km | B16: 3.85 | C16: 喬登美語(祥安分校) | D16: 私立尼恩語文文理短期補習班 | E16: 桃園市 | F16: 平鎮區 | G16: 桃園市平鎮區湧安里湧安路44號 | H16: 03 419 2435 | I16: ange198100@yahoo.com.tw | J16: 官網 | K16: 4.8 | L16: 41 | M16: 小型 | N16: 2 | O16: 36.15 | P16: 109.63 | Q16: 12 | R16: 4 | S16: 186 | T16: 80 | U16: 文理類,外語類 | V16: 2013-05-15 | W16: 王錦慧 | X16: 張國樑 | Y16: phone | Z16: 立案頁 | AA16: 地圖 | AB16: 24.894544 | AC16: 121.20374
A17: 0–5 km | B17: 4.35 | C17: 佑育語文文理短期補習班 | E17: 桃園市 | F17: 楊梅區 | G17: 桃園市楊梅區新榮里富榮路15號2樓 | H17: 03 490 6733 | K17: 5 | L17: 2 | AA17: 地圖 | AB17: 24.956819 | AC17: 121.16269
A18: 0–5 km | B18: 4.39 | C18: 長頸鹿美語-平鎮文化分校 文化國小補習班推薦 課輔班 兒童美語 國小英文 國小美語 小一先修班 正音班 英檢班 | D18: 私立卓越大文理短期補習班 | E18: 桃園市 | F18: 平鎮區 | G18: 桃園市平鎮區復旦里文化街186號 | H18: 03 493 1210 | I18: jingjing1155@yahoo.com.tw | J18: 官網 | K18: 4.8 | L18: 25 | M18: 小型 | N18: 2 | O18: 30.04 | P18: 132.1 | Q18: 2 | R18: 1 | S18: 30 | U18: 文理類 | V18: 2009-07-06 | W18: 胡菁芬 | X18: 胡菁芬 | Y18: address | Z18: 立案頁 | AA18: 地圖 | AB18: 24.952596 | AC18: 121.20315
A19: 0–5 km | B19: 4.4 | C19: 雅典音樂語文短期補習班 | D19: 私立雅典音樂語文短期補習班 | E19: 桃園市 | F19: 平鎮區 | G19: 桃園市平鎮區復旦里文化街180號 | H19: 03 493 5080 | I19: yinyizu@yahoo.com.tw | K19: 1 | L19: 1 | M19: 大型 | N19: 9 | O19: 67.31 | P19: 115.54 | Q19: 9 | R19: 1 | S19: 270 | T19: 90 | U19: 外語類,音樂、舞蹈類 | V19: 2006-12-22 | W19: 鄞薏如 | X19: 鄞薏如 | Y19: address | Z19: 立案頁 | AA19: 地圖 | AB19: 24.952707 | AC19: 121.20313
A20: 0–5 km | B20: 4.41 | C20: 奧斯汀美語 微思分校 | D20: 私立微思文理短期補習班 | E20: 桃園市 | F20: 平鎮區 | G20: 桃園市平鎮區復旦里復旦路二段150巷271號 | H20: 03 494 0020 | I20: blli8216@yahoo.com.tw | J20: 官網 | K20: 5 | L20: 95 | M20: 小型 | N20: 4 | O20: 59.98 | P20: 138.34 | Q20: 12 | R20: 2 | S20: 148 | T20: 96 | U20: 文理類 | V20: 2025-04-30 | W20: 廖偉宏 | X20: 廖偉宏 | Y20: address | Z20: 立案頁 | AA20: 地圖 | AB20: 24.953066 | AC20: 121.20272
A21: 0–5 km | B21: 4.47 | C21: 奧斯汀美語中平分校(松勇校) | D21: 私立睿儀文理短期補習班 | E21: 桃園市 | F21: 中壢區 | G21: 桃園市中壢區過嶺里松勇路39號 | H21: 03 420 0817 | I21: shm7415@gmail.com | J21: 官網 | K21: 4.3 | L21: 29 | M21: 小型 | N21: 4 | O21: 70.62 | P21: 158.28 | Q21: 8 | R21: 7 | S21: 117 | T21: 74 | U21: 文理類,外語類 | V21: 2023-04-27 | W21: 許惠敏 | X21: 王奕翔 | Y21: address | Z21: 立案頁 | AA21: 地圖 | AB21: 24.959013 | AC21: 121.16653
A22: 0–5 km | B22: 4.53 | C22: 小學堂文教機構 | Live互動美語 | D22: 私立世一語文數學短期補習班 | E22: 桃園市 | F22: 平鎮區 | G22: 桃園市平鎮區復旦里文化街88號 | H22: 03 281 0128 | I22: julie_hmm@yahoo.com.tw | J22: 官網 | K22: 4.9 | L22: 121 | M22: 小型 | N22: 3 | O22: 44.88 | P22: 175.56 | Q22: 5 | R22: 1 | S22: 60 | T22: 24 | U22: 外語類,其他類 | V22: 2014-05-06 | W22: 黃美寧 | X22: 黃慶豊 | Y22: phone | Z22: 立案頁 | AA22: 地圖 | AB22: 24.95416 | AC22: 121.20301
A23: 0–5 km | B23: 4.54 | C23: 菲比斯英語 | D23: 私立菲比斯文理短期補習班 | E23: 桃園市 | F23: 中壢區 | G23: 桃園市中壢區過嶺里松德路125號 | H23: 03 420 5140 | I23: joanne750312@gmail.com | K23: 5 | L23: 6 | M23: 小型 | N23: 2 | O23: 42.47 | P23: 146.67 | Q23: 9 | R23: 2 | S23: 153 | T23: 68 | U23: 文理類 | V23: 2022-11-22 | W23: 鍾瑞敏 | X23: 黃俊偉 | Y23: address | Z23: 立案頁 | AA23: 地圖 | AB23: 24.960269 | AC23: 121.16897
A24: 0–5 km | B24: 4.56 | C24: 建如文理補習班、MPM數學、空中美語文化分校 | D24: 私立建如語文文理珠心算短期補習班 | E24: 桃園市 | F24: 平鎮區 | G24: 桃園市平鎮區復旦里文化街72號 | H24: 03 493 8800 | I24: cw.c224@msa.hinet.net | J24: 官網 | K24: 4.7 | L24: 16 | M24: 中型 | N24: 5 | O24: 119.22 | P24: 210.87 | Q24: 6 | R24: 6 | S24: 708 | T24: 118 | U24: 文理類,外語類 | V24: 2008-10-09 | W24: 張謙旺 | X24: 張謙旺 | Y24: address | Z24: 立案頁 | AA24: 地圖 | AB24: 24.954507 | AC24: 121.20301
A25: 0–5 km | B25: 4.57 | C25: 明子園幼兒園/課後班/安親班/文化國小安親/美語安親/ | E25: 桃園市 | F25: 平鎮區 | G25: 桃園市平鎮區復旦里文化街68巷6號 | H25: 03 494 5172 | K25: 4.4 | L25: 58 | AA25: 地圖 | AB25: 24.954797 | AC25: 121.20273
A26: 0–5 km | B26: 4.59 | C26: 大山美語文理補習班 | D26: 私立大山美語文理短期補習班 | E26: 桃園市 | F26: 平鎮區 | G26: 桃園市平鎮區北富里金陵路三段150巷2弄37-2號 | H26: 03 458 9120 | I26: a0920138250@gmail.com | K26: 3.8 | L26: 5 | M26: 小型 | N26: 4 | O26: 67.2 | P26: 180.97 | Q26: 4 | R26: 1 | S26: 52 | T26: 24 | U26: 文理類,外語類 | V26: 2008-09-28 | W26: 魏奕萱 | X26: 劉效謙 | Y26: phone | Z26: 立案頁 | AA26: 地圖 | AB26: 24.925142 | AC26: 121.22331
A27: 0–5 km | B27: 4.6 | C27: 小森林美語 | D27: 私立小森林美語短期補習班 | E27: 桃園市 | F27: 平鎮區 | G27: 桃園市平鎮區復興里文化街61號 | I27: sherrybennykammy71@gmail.com | K27: 4.5 | L27: 16 | M27: 中型 | N27: 4 | O27: 73.27 | P27: 239.62 | Q27: 4 | R27: 3 | S27: 76 | T27: 76 | U27: 外語類 | V27: 2002-10-24 | W27: 鍾木昌 | X27: 林佳慧 | Y27: name | Z27: 立案頁 | AA27: 地圖 | AB27: 24.954864 | AC27: 121.20313
A28: 0–5 km | B28: 4.62 | C28: 加大美語 | D28: 私立加大美語珠心算短期補習班 | E28: 桃園市 | F28: 平鎮區 | G28: 桃園市平鎮區復興里廣德街93號 | H28: 03 492 2061 | I28: chiata1688@gmail.com | K28: 3.5 | L28: 8 | M28: 小型 | N28: 3 | O28: 57.51 | P28: 104.26 | Q28: 3 | R28: 2 | S28: 45 | T28: 30 | U28: 外語類,商類：珠算、心算、會計 | V28: 2001-03-09 | W28: 黃儷仁 | X28: 黃儷仁 | Y28: address | Z28: 立案頁 | AA28: 地圖 | AB28: 24.953768 | AC28: 121.20523
A29: 0–5 km | B29: 4.75 | C29: 錢老師語文音樂文理短期補習班 | D29: 私立錢老師語文音樂文理短期補習班 | E29: 桃園市 | F29: 平鎮區 | G29: 桃園市平鎮區復興里復興街16號 | H29: 0912 252 612 | I29: s966928@gmail.com | K29: 4.8 | L29: 20 | M29: 小型 | N29: 4 | O29: 88.42 | P29: 178.97 | Q29: 4 | R29: 1 | S29: 72 | T29: 23 | U29: 文理類,外語類 | V29: 2014-11-18 | W29: 錢曉昱 | X29: 錢曉昱 | Y29: address | Z29: 立案頁 | AA29: 地圖 | AB29: 24.954612 | AC29: 121.20609
A30: 0–5 km | B30: 4.77 | C30: 葛洛莉英語-平鎮校Ping Jen(文化國小 復旦國小 平興國小)平鎮兒童美語 平鎮英文補習班 平鎮美語 國小英文 國中英文 小一新生 高中英文 | D30: 私立春華英語會話短期補習班 | E30: 桃園市 | F30: 平鎮區 | G30: 桃園市平鎮區環南路66巷17弄14衖26號 | H30: 03 494 8585 | I30: annachang1129@gmail.com | J30: 官網 | K30: 5 | L30: 757 | M30: 大型 | N30: 7 | O30: 147.25 | P30: 710.16 | Q30: 7 | R30: 21 | S30: 105 | T30: 105 | U30: 外語類 | V30: 2002-08-30 | W30: 張國俐 | X30: 廖俊傑 | Y30: address | Z30: 立案頁 | AA30: 地圖 | AB30: 24.955237 | AC30: 121.20546
A31: 0–5 km | B31: 4.98 | C31: 哥倫匹亞語文短期補習班 | D31: 私立龍科國際美語村文理短期補習班 | E31: 桃園市 | F31: 龍潭區 | G31: 桃園市龍潭區八德里梅龍路500號 | H31: 03 489 1225 | I31: mikechang@arthouses.com.tw | M31: 大型 | N31: 4 | O31: 147.84 | P31: 552.25 | Q31: 6 | R31: 1 | S31: 191 | T31: 92 | U31: 文理類,外語類 | V31: 2024-01-31 | W31: 張乃元 | X31: 張乃元 | Y31: address | Z31: 立案頁 | AA31: 地圖 | AB31: 24.877042 | AC31: 121.19122
A32: 0–5 km | B32: 4.98 | C32: 龍潭國際美語村 | D32: 私立龍科國際美語村文理短期補習班 | E32: 桃園市 | F32: 龍潭區 | G32: 桃園市龍潭區八德里梅龍路500號 | H32: 03 489 1225 | I32: mikechang@arthouses.com.tw | J32: 官網 | K32: 4.6 | L32: 8 | M32: 大型 | N32: 4 | O32: 147.84 | P32: 552.25 | Q32: 6 | R32: 1 | S32: 191 | T32: 92 | U32: 文理類,外語類 | V32: 2024-01-31 | W32: 張乃元 | X32: 張乃元 | Y32: address | Z32: 立案頁 | AA32: 地圖 | AB32: 24.877042 | AC32: 121.19122
A33: 5–10 km | B33: 5 | C33: 薇閣語文短期補習班 | D33: 私立薇閣語文短期補習班 | E33: 桃園市 | F33: 平鎮區 | G33: 桃園市平鎮區北興里金陵路二段360號 | H33: 03 457 0932 | I33: amilus326@gmail.com | K33: 3.6 | L33: 20 | M33: 小型 | N33: 3 | O33: 67.21 | P33: 120.61 | Q33: 3 | R33: 3 | S33: 84 | T33: 20 | U33: 外語類 | V33: 2010-12-21 | W33: 杜壹岳 | X33: 邱佩玲 | Y33: address | Z33: 立案頁 | AA33: 地圖 | AB33: 24.934987 | AC33: 121.22499
A34: 5–10 km | B34: 5.04 | C34: 吉的堡美語學校 | D34: 私立聖儒美語短期補習班 | E34: 桃園市 | F34: 平鎮區 | G34: 桃園市平鎮區北興里金陵路二段377-2號 | H34: 03 428 8883 | I34: deep322611@yahoo.com.tw | J34: 官網 | K34: 3.3 | L34: 7 | M34: 小型 | N34: 2 | O34: 47.52 | P34: 155.16 | Q34: 2 | R34: 5 | S34: 38 | T34: 38 | U34: 外語類 | V34: 2006-05-11 | W34: 徐毓惠 | X34: 徐毓惠 | Y34: address | Z34: 立案頁 | AA34: 地圖 | AB34: 24.935666 | AC34: 121.22517
A35: 5–10 km | B35: 5.51 | C35: 夏山美語 | D35: 私立夏山美語短期補習班 | E35: 桃園市 | F35: 龍潭區 | G35: 桃園市龍潭區百年里百年五街43號 | H35: 03 480 2263 | J35: 官網 | K35: 5 | L35: 3 | M35: 小型 | N35: 2 | O35: 41.06 | P35: 96.96 | Q35: 2 | R35: 1 | S35: 48 | T35: 48 | U35: 外語類 | V35: 2016-07-19 | W35: 范采綺 | X35: 范采綺 | Y35: address | Z35: 立案頁 | AA35: 地圖 | AB35: 24.88024 | AC35: 121.21032
A36: 5–10 km | B36: 5.51 | C36: 喬登美語(潛龍分校) | E36: 桃園市 | F36: 龍潭區 | G36: 桃園市龍潭區烏樹林里中豐路418之1號 | AA36: 地圖 | AB36: 24.881283 | AC36: 121.21193
A37: 5–10 km | B37: 5.81 | C37: 快樂園語文文理短期補習班 | D37: 私立快樂園語文文理短期補習班 | E37: 桃園市 | F37: 楊梅區 | G37: 桃園市楊梅區上田里楊新路四段37巷3弄19號 | H37: 03 288 9060 | I37: happy370319@gmail.com | J37: 官網 | K37: 5 | L37: 4 | M37: 小型 | N37: 4 | O37: 71.44 | P37: 153.88 | Q37: 4 | R37: 4 | S37: 58 | T37: 16 | U37: 文理類,外語類 | V37: 2010-09-16 | W37: 蘇少庠 | X37: 蘇少庠 | Y37: address | Z37: 立案頁 | AA37: 地圖 | AB37: 24.936586 | AC37: 121.12338
A38: 5–10 km | B38: 7.6 | C38: 吉的堡美語學校(中壢大崙分校) | E38: 桃園市 | F38: 中壢區 | G38: 桃園市中壢區內厝里中正路四段70號 | H38: 03 498 6090 | J38: 官網 | K38: 4.5 | L38: 8 | AA38: 地圖 | AB38: 24.988563 | AC38: 121.18099
A39: 5–10 km | B39: 7.6 | C39: 學匯語文文理數學補習班 大崙校 | D39: 私立學匯語文文理數學短期補習班大崙分班 | E39: 桃園市 | F39: 中壢區 | G39: 桃園市中壢區內厝里中正路四段66號 | H39: 03 408 0369 | I39: sharewe112010@yahoo.com.tw | J39: 官網 | K39: 4.8 | L39: 41 | M39: 中型 | N39: 4 | O39: 104.14 | P39: 214.14 | Q39: 10 | R39: 1 | S39: 219 | T39: 52 | U39: 文理類,外語類,其他類 | V39: 2021-09-01 | W39: 廖楷文 | X39: 廖麒文 | Y39: address | Z39: 立案頁 | AA39: 地圖 | AB39: 24.98856 | AC39: 121.18103
A40: 5–10 km | B40: 7.61 | C40: 奇飛美語珠算短期補習班 | D40: 私立祥耀文理短期補習班 | E40: 桃園市 | F40: 中壢區 | G40: 桃園市中壢區內厝里中正路四段85號2樓 | H40: 03 498 0101 | I40: a0916826998@gmail.com | M40: 小型 | N40: 2 | O40: 56.26 | P40: 151.38 | Q40: 16 | R40: 5 | S40: 368 | T40: 146 | U40: 文理類,外語類 | V40: 2023-04-27 | W40: 林玲瓏 | X40: 林鈴蓁 | Y40: phone | Z40: 立案頁 | AA40: 地圖 | AB40: 24.988681 | AC40: 121.18036
...

Sheet 全台英文補習班
A1: 縣市 | B1: 行政區 | C1: 立案名稱 | D1: 地址 | E1: 電話 | F1: Email | G1: 規模 | H1: 教室數 | I1: 教室面積(㎡) | J1: 班舍總面積(㎡) | K1: 核准班級數 | L1: 登記師資(人) | M1: 核定容量(人) | N1: 英文科核定(人) | O1: 英文相關核准科目 | P1: 立案類別 | Q1: 立案情形 | R1: 立案日期 | S1: 負責人 | T1: 班主任 | U1: 立案頁
A2: 臺北市 | B2: 中山區 | C2: 何嘉仁文教事業股份有限公司附設臺北市私立智仁文理短期補習班 | D2: 中山區民權東路2段107號4樓、7樓、6樓 | E2: 25928378 | F2: hs3381@hess.com.tw | G2: 大型 | H2: 39 | I2: 1149.74 | J2: 2825.37 | K2: 203 | L2: 38 | M2: 12180 | N2: 1740 | O2: 英語 | P2: 外語類 | Q2: 已立案 | R2: 2006-01-01 | S2: 秦鴻筠 | T2: 李易儒 | U2: 立案頁
A3: 臺北市 | B3: 中山區 | C3: 創勝文教股份有限公司附設臺北市私立創勝文教英語短期補習班 | D3: 中山區朱崙街60號2樓、2樓之1、2樓之2 | E3: 27713072 | F3: ntecontact@gmail.com | G3: 小型 | H3: 2 | I3: 105.71 | J3: 193.89 | K3: 2 | L3: 10 | M3: 120 | N3: 120 | O3: 英文 | P3: 外語類 | Q3: 已立案 | R3: 2015-12-09 | S3: 王梓雯 | T3: 洪榆涵 | U3: 立案頁
A4: 臺北市 | B4: 中山區 | C4: 台灣拓人教育事業股份有限公司附設拓人文理短期補習班大直分班 | D4: 中山區明水路581巷13弄1號1樓 | E4: 2533-9636 | F4: tact.a001@msa.hinet.net | G4: 小型 | H4: 2 | I4: 62.82 | J4: 124 | K4: 15 | L4: 32 | M4: 780 | N4: 156 | O4: 英語 | P4: 文理類,外語類 | Q4: 已立案 | R4: 2009-03-01 | S4: 李萬吉 | T4: 陳芝毓 | U4: 立案頁
A5: 臺北市 | B5: 中山區 | C5: 奇異松股份有限公司附設臺北市私立奇異鳥懷恩美語文理短期補習班 | D5: 中山區松江路293之203號2樓 | E5: 25185186 | F5: aes.sj5186@gmail.com | G5: 小型 | H5: 2 | I5: 68.73 | J5: 149.83 | K5: 4 | L5: 15 | M5: 240 | N5: 240 | O5: 英語 | P5: 外語類 | Q5: 已立案 | R5: 2015-08-14 | S5: 奇異松股份有限公司(林秀姿) | T5: 謝牧音 | U5: 立案頁
A6: 臺北市 | B6: 中山區 | C6: 安宸文教事業有限公司附設臺北市私立安宸文理短期補習班 | D6: 中山區松江路186之1號2樓 | E6: (02)-2100-1585 | F6: cc186@meikoschool.com.tw | G6: 小型 | H6: 1 | I6: 32.88 | J6: 82.8 | K6: 5 | L6: 8 | M6: 135 | N6: 27 | O6: 英文 | P6: 文理類,外語類 | Q6: 已立案 | R6: 2026-07-29 | S6: 安宸文教事業有限公司(負責人：李淑宜) | T6: 李巧筠 | U6: 立案頁
A7: 臺北市 | B7: 中山區 | C7: 臺北市私立偉迪文理技藝短期補習班 | D7: 中山區長春路172號6樓 | E7: 25060028 | F7: tia34010741@gmail.com | G7: 小型 | H7: 4 | I7: 69.66 | J7: 113.78 | K7: 28 | L7: 7 | M7: 560 | N7: 80 | O7: 美語 | P7: 外語類 | Q7: 已立案 | R7: 2003-10-01 | S7: 蘇正忻 | T7: 金莉軒 | U7: 立案頁
A8: 臺北市 | B8: 中山區 | C8: 臺北市私立傑聲語文短期補習班 | D8: 中山區明水路397巷2弄6號1樓 | E8: 25328522 | F8: ally@jasonschool.com.tw | G8: 小型 | H8: 3 | I8: 44.82 | J8: 104.38 | K8: 2 | L8: 2 | M8: 34 | N8: 34 | O8: 美語 | P8: 外語類 | Q8: 已立案 | R8: 2003-05-01 | S8: 于維芝 | T8: 周吟倩 | U8: 立案頁
A9: 臺北市 | B9: 中山區 | C9: 臺北市私立冠英文理短期補習班南京分班 | D9: 中山區復興北路50號3樓 | E9: 27196265 | F9: kenglish168@gmail.com | G9: 中型 | H9: 3 | I9: 148.82 | J9: 232.991 | K9: 3 | L9: 21 | M9: 180 | N9: 180 | O9: 英文 | P9: 外語類 | Q9: 已立案 | R9: 2013-01-31 | S9: 王馨敏 | T9: 王馨敏 | U9: 立案頁
A10: 臺北市 | B10: 中山區 | C10: 臺北市私立凱斯文理短期補習班 | D10: 中山區南京東路3段21號3樓及4樓 | E10: 02-25026622 | F10: catsnj@catsedugroup.com.tw | G10: 大型 | H10: 11 | I10: 199.16 | J10: 442.06 | K10: 66 | L10: 28 | M10: 3960 | N10: 660 | O10: 英語 | P10: 外語類 | Q10: 已立案 | R10: 2002-09-01 | S10: 王永弘 | T10: 朱加君 | U10: 立案頁
A11: 臺北市 | B11: 中山區 | C11: 臺北市私立凱斯文理短期補習班大直分班 | D11: 中山區明水路565號(1層) | E11: 25329222 | F11: alisa03220@gmail.com | G11: 中型 | H11: 5 | I11: 66.58 | J11: 120.09 | K11: 20 | L11: 29 | M11: 1100 | N11: 220 | O11: 英語 | P11: 外語類 | Q11: 已立案 | R11: 2013-04-24 | S11: 王永弘 | T11: 吳敏蘭 | U11: 立案頁
A12: 臺北市 | B12: 中山區 | C12: 臺北市私立喬誠語文短期補習班 | D12: 中山區民權東路3段63號4樓、65號4樓 | E12: 25181888 | F12: fun117kimo@yahoo.com.tw | G12: 小型 | H12: 2 | I12: 51.12 | J12: 166.56 | K12: 2 | L12: 3 | M12: 84 | N12: 84 | O12: 美語 | P12: 外語類 | Q12: 已立案 | R12: 2004-09-01 | S12: 郭清蓮 | T12: 郭清蓮 | U12: 立案頁
A13: 臺北市 | B13: 中山區 | C13: 臺北市私立安德信語文資訊短期補習班 | D13: 中山區北安路554巷21號1樓、地下1樓 | E13: 25334700 | F13: joydz4700@gmail.com | G13: 中型 | H13: 7 | I13: 141.28 | J13: 316.3 | K13: 18 | L13: 3 | M13: 180 | N13: 30 | O13: 英語 | P13: 外語類,資訊類 | Q13: 已立案 | R13: 2000-01-01 | S13: 鄧榮禎 | T13: 鄧榮禎 | U13: 立案頁
A14: 臺北市 | B14: 中山區 | C14: 臺北市私立小朋友創意文理短期補習班 | D14: 中山區明水路397巷7弄25號1樓 | E14: (02)28059922 | F14: Eyeleveldazhi@gmail.com | G14: 小型 | H14: 3 | I14: 48.77 | J14: 98.5 | K14: 1 | L14: 1 | M14: 10 | N14: 10 | O14: 英語 | P14: 文理類,外語類 | Q14: 已立案 | R14: 2023-05-25 | S14: 蔡嘉琪 | T14: 蔡嘉琪 | U14: 立案頁
A15: 臺北市 | B15: 中山區 | C15: 臺北市私立得勝者文理短期補習班 | D15: 中山區龍江路377巷22號1樓 | E15: 2504-7300 | G15: 小型 | H15: 3 | I15: 56.68 | J15: 84.16 | K15: 4 | L15: 3 | M15: 188 | N15: 141 | O15: 英文 | P15: 文理類,外語類 | Q15: 已立案 | R15: 2010-01-04 | S15: 郭献哲 | T15: 鍾伶俐 | U15: 立案頁
A16: 臺北市 | B16: 中山區 | C16: 臺北市私立快樂芳庭語文美術短期補習班 | D16: 中山區民權東路1段58巷1號1、2、3樓 | E16: 25719899 | F16: beatrice.beatricelin@gmail.com | G16: 小型 | H16: 4 | I16: 110.11 | J16: 176.01 | K16: 2 | L16: 4 | M16: 120 | N16: 60 | O16: 美語 | P16: 外語類,美術、書法、攝影、美工設計、圍棋類 | Q16: 已立案 | R16: 2001-05-01 | S16: 林碧合 | T16: 陳淑茹 | U16: 立案頁
A17: 臺北市 | B17: 中山區 | C17: 臺北市私立文盛文理短期補習班 | D17: 中山區復興北路430巷16號1樓 | E17: 2500-7586 | F17: janelai0216@gmail.com | G17: 小型 | H17: 2 | I17: 37.57 | J17: 100 | K17: 14 | L17: 6 | M17: 434 | N17: 62 | O17: 英文 | P17: 文理類,外語類,音樂、舞蹈類,美術、書法、攝影、美工設計、圍棋類 | Q17: 已立案 | R17: 2007-03-13 | S17: 王成正 | T17: 王成正 | U17: 立案頁
A18: 臺北市 | B18: 中山區 | C18: 臺北市私立本能文理短期補習班 | D18: 中山區民權東路3段43號2樓 | E18: 25082618 | F18: wuchangbaby@gmail.com | G18: 小型 | H18: 2 | I18: 38.23 | J18: 84.67 | K18: 10 | L18: 3 | M18: 310 | N18: 62 | O18: 英文 | P18: 外語類 | Q18: 已立案 | R18: 2009-07-01 | S18: 陳霈甄 | T18: 張歆立 | U18: 立案頁
A19: 臺北市 | B19: 中山區 | C19: 臺北市私立朵朵老師文理短期補習班 | D19: 中山區北安路630巷25弄9號1樓 | E19: (02)8509-8858 | F19: li.taitsung@gmail.com | G19: 小型 | H19: 2 | I19: 35.56 | J19: 71 | K19: 4 | L19: 2 | M19: 116 | N19: 58 | O19: 英文、國文、數學、科學 | P19: 外語類 | Q19: 已立案 | R19: 2001-12-01 | S19: 黎岱宗 | T19: 蔡佩鈞 | U19: 立案頁
A20: 臺北市 | B20: 中山區 | C20: 臺北市私立琴生語文音樂短期補習班 | D20: 中山區北安路588巷12號1樓 | E20: 25320125 | F20: cmd1@yamahacsm.com.tw | G20: 中型 | H20: 7 | I20: 73.21 | J20: 146.74 | K20: 14 | L20: 29 | M20: 840 | N20: 420 | O20: 英文 | P20: 外語類 | Q20: 已立案 | R20: 1993-11-01 | S20: 梁啓慧 | T20: 徐智華 | U20: 立案頁
A21: 臺北市 | B21: 中山區 | C21: 臺北市私立睿智大直語文短期補習班 | D21: 中山區北安路608巷5弄6號（1、2樓） | E21: 25324761 | F21: dazhiaces@gmail.com | G21: 小型 | H21: 2 | I21: 76.36 | J21: 143.52 | K21: 2 | L21: 15 | M21: 120 | N21: 120 | O21: 英文 | P21: 外語類 | Q21: 已立案 | R21: 2007-06-27 | S21: FRANCE RICHARD THOMAS | T21: 吳雲潔 | U21: 立案頁
A22: 臺北市 | B22: 中山區 | C22: 臺北市私立科建語文文理短期補習班 | D22: 中山區松江路90巷9號1、3樓及地下室 | E22: 25641600 | F22: manager2k@kojen-els.com.tw | G22: 大型 | H22: 8 | I22: 204 | J22: 389.41 | K22: 36 | L22: 54 | M22: 2160 | N22: 240 | O22: 英文 | P22: 外語類 | Q22: 已立案 | R22: 1976-07-01 | S22: 李婉如 | T22: 李婉如 | U22: 立案頁
A23: 臺北市 | B23: 中山區 | C23: 臺北市私立科豆文理短期補習班 | D23: 中山區復興北路166號3樓 | E23: 27191913 | F23: cuddle27222007@gmail.com | G23: 中型 | H23: 5 | I23: 84.62 | J23: 183.39 | K23: 12 | L23: 1 | M23: 720 | N23: 180 | O23: 英文 | P23: 文理類,外語類,資訊類,其他類 | Q23: 已立案 | R23: 2014-07-28 | S23: 邱楷甯 | T23: 段輝陽 | U23: 立案頁
A24: 臺北市 | B24: 中山區 | C24: 臺北市私立艾沛思美語文理短期補習班 | D24: 中山區民權東路3段31號2樓 | E24: 25150890 | F24: ipaxschool@gmail.com | G24: 小型 | H24: 1 | I24: 40.9 | J24: 72.81 | K24: 5 | L24: 1 | M24: 170 | N24: 170 | O24: 英文 | P24: 外語類 | Q24: 已立案 | R24: 2017-02-16 | S24: 楊宜真 | T24: 楊宜真 | U24: 立案頁
A25: 臺北市 | B25: 中山區 | C25: 臺北市私立藝起玩文理技藝短期補習班 | D25: 中山區民權西路20號6樓之5 | E25: 0937429426 | F25: tuttiarts.studio@gmail.com | G25: 小型 | H25: 2 | I25: 44.67 | J25: 81.93 | K25: 28 | L25: 19 | M25: 672 | N25: 96 | O25: 英文 | P25: 文理類,外語類,音樂、舞蹈類,美術、書法、攝影、美工設計、圍棋類 | Q25: 已立案 | R25: 2024-12-06 | S25: 葉仰真 | T25: 葉仰真 | U25: 立案頁
A26: 臺北市 | B26: 中山區 | C26: 臺北市私立貝斯語文短期補習班 | D26: 中山區南京東路3段200號2樓之1 | E26: 27780408 | F26: bethenglish1991@gmail.com | G26: 中型 | H26: 6 | I26: 134.01 | J26: 169.52 | K26: 6 | L26: 12 | M26: 360 | N26: 360 | O26: 英文 | P26: 外語類 | Q26: 已立案 | R26: 2000-08-01 | S26: 王宗輝 | T26: 王宗輝 | U26: 立案頁
A27: 臺北市 | B27: 中山區 | C27: 臺北市私立陸翁藝術美術技藝文理短期補習班 | D27: 中山區吉林路144巷18號1樓 | E27: 25681607 | F27: luwengart@gmail.com | G27: 小型 | H27: 3 | I27: 37.87 | J27: 77.56 | K27: 12 | L27: 1 | M27: 372 | N27: 124 | O27: 英文 | P27: 外語類,資訊類,美術、書法、攝影、美工設計、圍棋類 | Q27: 已立案 | R27: 2011-04-01 | S27: 陸孟新 | T27: 翁姍慧 | U27: 立案頁
... A52: 臺北市 | B52: 中正區 | C52: 臺北市私立凱德語文短期補習班 | D52: 中正區羅斯福路2段68號6樓 | E52: 23961880 | F52: hsiehailing2000@gmail.com | G52: 小型 | H52: 2 | I52: 54.81 | J52: 118.38 | K52: 2 | L52: 2 | M52: 90 | N52: 90 | O52: 英文 | P52: 外語類 | Q52: 已立案 | R52: 2009-10-05 | S52: 謝艾伶 | T52: 謝艾伶 | U52: 立案頁
A53: 臺北市 | B53: 中正區 | C53: 臺北市私立劉媽媽語文短期補習班 | D53: 中正區寧波西街80號2樓 | E53: 0928107969 | G53: 小型 | H53: 2 | I53: 85.5 | J53: 85.5 | K53: 4 | L53: 2 | M53: 240 | N53: 120 | O53: 英語 | P53: 外語類 | Q53: 已立案 | R53: 1984-12-10 | S53: 劉林純美 | T53: 劉家郁 | U53: 立案頁
A54: 臺北市 | B54: 中正區 | C54: 臺北市私立同文館語文文理短期補習班 | D54: 中正區信義路2段91號4樓之4 | E54: 23937795 | F54: tonwenkuan@gmail.com | G54: 小型 | H54: 3 | I54: 49.57 | J54: 110.04 | K54: 4 | L54: 2 | M54: 56 | N54: 28 | O54: 英文 | P54: 外語類 | Q54: 已立案 | R54: 2005-08-01 | S54: 鄭仁雨 | T54: 涂鈺芳 | U54: 立案頁
A55: 臺北市 | B55: 中正區 | C55: 臺北市私立天肯外語美術文理技藝短期補習班 | D55: 中正區羅斯福路3段272號9樓 | E55: 23696180 | F55: tianken.bonjour@gmail.com | G55: 中型 | H55: 5 | I55: 80.31 | J55: 190.18 | K55: 18 | L55: 11 | M55: 1080 | N55: 180 | O55: 英文 | P55: 外語類 | Q55: 已立案 | R55: 2011-04-01 | S55: 李欣怡 | T55: 李欣怡 | U55: 立案頁
A56: 臺北市 | B56: 中正區 | C56: 臺北市私立學智文理短期補習班 | D56: 中正區許昌街17號6樓之3 | E56: 23895212 | F56: learn23895212@gmail.com | G56: 小型 | H56: 1 | I56: 187.66 | J56: 196.16 | K56: 10 | L56: 21 | M56: 600 | N56: 120 | O56: 英語 | P56: 文理類,外語類 | Q56: 已立案 | R56: 2010-08-31 | S56: 劉君強 | T56: 劉君強 | U56: 立案頁
A57: 臺北市 | B57: 中正區 | C57: 臺北市私立小小林圍棋文理技藝短期補習班古亭分班 | D57: 中正區羅斯福路2段70號7樓之5 | E57: 2356-7337 | F57: ron19890806@gmail.com | G57: 小型 | H57: 4 | I57: 107.99 | J57: 125.58 | K57: 36 | L57: 18 | M57: 2160 | N57: 240 | O57: 美語 | P57: 外語類,美術、書法、攝影、美工設計、圍棋類 | Q57: 已立案 | R57: 2017-04-28 | S57: 林耕平 | T57: 周佳盈 | U57: 立案頁
A58: 臺北市 | B58: 中正區 | C58: 臺北市私立彭湘平英文文理技藝短期補習班 | D58: 中正區信義路2段91號5樓之2、之3 | E58: 23517722 | F58: f90841015@ntu.edu.tw | G58: 小型 | H58: 4 | I58: 117.15 | J58: 192.34 | K58: 8 | L58: 4 | M58: 160 | N58: 80 | O58: 英文 | P58: 外語類 | Q58: 已立案 | R58: 2000-07-01 | S58: 徐嘉偉 | T58: 徐嘉偉 | U58: 立案頁
A59: 臺北市 | B59: 中正區 | C59: 臺北市私立承淞語文文理短期補習班 | D59: 中正區杭州南路1段14巷21號2樓 | E59: 23210826 | F59: dongmen000@yahoo.com.tw | G59: 小型 | H59: 4 | I59: 56.18 | J59: 99.68 | K59: 5 | L59: 9 | M59: 160 | N59: 32 | O59: 美語 | P59: 外語類 | Q59: 已立案 | R59: 2000-11-01 | S59: 廖彩絹 | T59: 林淑絹 | U59: 立案頁
A60: 臺北市 | B60: 中正區 | C60: 臺北市私立掘奇地文理技藝短期補習班 | D60: 中正區和平西路2段90巷4號1樓 | E60: 23016565 | F60: justkids2016@gmail.com | G60: 小型 | H60: 3 | I60: 41.12 | J60: 81.54 | K60: 7 | L60: 9 | M60: 140 | N60: 20 | O60: 英文 | P60: 外語類 | Q60: 已立案 | R60: 1992-01-01 | S60: 鐘語蓁 | T60: 鐘語蓁 | U60: 立案頁
A61: 臺北市 | B61: 中正區 | C61: 臺北市私立文城古亭文理短期補習班 | D61: 中正區羅斯福路2段70號10樓 | E61: (02)2369-1090 | F61: joey.wang@wmch.net | G61: 小型 | H61: 2 | I61: 43.36 | J61: 92.36 | K61: 8 | L61: 40 | M61: 288 | N61: 36 | O61: 英語 | P61: 文理類,外語類 | Q61: 已立案 | R61: 2011-01-28 | S61: 宋狄翰 | T61: 卓嘉惠 | U61: 立案頁
A62: 臺北市 | B62: 中正區 | C62: 臺北市私立新小學館文理短期補習班 | D62: 中正區漢口街1段140、142號2樓 | E62: 23120259 | G62: 小型 | H62: 3 | I62: 73.9 | J62: 118.03 | K62: 15 | L62: 5 | M62: 330 | N62: 66 | O62: 英語 | P62: 外語類 | Q62: 已立案 | R62: 2005-05-01 | S62: 尉遲佩琪 | T62: 呂文中 | U62: 立案頁
A63: 臺北市 | B63: 中正區 | C63: 臺北市私立時代國際語文短期補習班 | D63: 中正區漢口街1段3、5、9、11號3樓 | E63: 0266178688 | F63: rachel.chen@language-world.com.tw | G63: 小型 | H63: 4 | I63: 101 | J63: 188.61 | K63: 12 | L63: 58 | M63: 252 | N63: 84 | O63: 英文 | P63: 外語類 | Q63: 已立案 | R63: 2004-04-01 | S63: 鄭陳秋玉 | T63: 鄭淑賢 | U63: 立案頁
A64: 臺北市 | B64: 中正區 | C64: 臺北市私立時代國際語文短期補習班館前二分班 | D64: 中正區館前路34號8樓 | E64: 66178688 | F64: rachel.chen@language-world.com.tw | G64: 大型 | H64: 5 | I64: 212.5 | J64: 433.18 | K64: 3 | L64: 61 | M64: 180 | N64: 60 | O64: 英文 | P64: 外語類 | Q64: 已立案 | R64: 2009-02-23 | S64: 鄭陳秋玉 | T64: 鄭陳秋玉 | U64: 立案頁
...

Sheet 規模統計
A1: 規模統計
A2: 所有數字皆為公式，改動名錄分頁會自動重算。
A4: 楊梅 20 公里圈 — 整體
B5: 家數 | C5: 有立案資料 | D5: 有 Email | E5: 教室數中位數 | F5: 班舍面積中位數(㎡) | G5: 師資中位數(人) | H5: 平均班舍面積(㎡)
A6: 全部 | B6: =COUNTA(楊梅20km名錄!$A$2:$A$160) -> 159 | C6: =COUNTA(楊梅20km名錄!$D$2:$D$160) -> 120 | D6: =COUNTIF(楊梅20km名錄!$I$2:$I$160,"?*") -> 113 | E6: =MEDIAN(楊梅20km名錄!$N$2:$N$160) -> 4 | F6: =MEDIAN(楊梅20km名錄!$P$2:$P$160) -> 172.065 | G6: =MEDIAN(楊梅20km名錄!$R$2:$R$160) -> 3 | H6: =AVERAGE(楊梅20km名錄!$P$2:$P$160) -> 222.21258
A8: 楊梅 20 公里圈 — 依距離級距
A9: 距離級距 | B9: 家數 | C9: 有立案資料 | D9: 有 Email | E9: 平均教室數 | F9: 平均班舍面積(㎡) | G9: 平均師資(人) | H9: 大型
A10: 0–5 km | B10: =COUNTIF(楊梅20km名錄!$A$2:$A$160,$A10) -> 31 | C10: =COUNTIFS(楊梅20km名錄!$A$2:$A$160,$A10,楊梅20km名錄!$D$2:$D$160,"<>") -> 27 | D10: =COUNTIFS(楊梅20km名錄!$A$2:$A$160,$A10,楊梅20km名錄!$I$2:$I$160,"?*") -> 26 | E10: =IFERROR(AVERAGEIFS(楊梅20km名錄!$N$2:$N$160,楊梅20km名錄!$A$2:$A$160,$A10,楊梅20km名錄!$N$2:$N$160,">0"),"") -> 3.8148148 | F10: =IFERROR(AVERAGEIFS(楊梅20km名錄!$P$2:$P$160,楊梅20km名錄!$A$2:$A$160,$A10,楊梅20km名錄!$P$2:$P$160,">0"),"") -> 209.06333 | G10: =IFERROR(AVERAGEIFS(楊梅20km名錄!$R$2:$R$160,楊梅20km名錄!$A$2:$A$160,$A10,楊梅20km名錄!$R$2:$R$160,">0"),"") -> 4.2962963 | H10: =COUNTIFS(楊梅20km名錄!$A$2:$A$160,$A10,楊梅20km名錄!$M$2:$M$160,"大型") -> 4
A11: 5–10 km | B11: =COUNTIF(楊梅20km名錄!$A$2:$A$160,$A11) -> 23 | C11: =COUNTIFS(楊梅20km名錄!$A$2:$A$160,$A11,楊梅20km名錄!$D$2:$D$160,"<>") -> 17 | D11: =COUNTIFS(楊梅20km名錄!$A$2:$A$160,$A11,楊梅20km名錄!$I$2:$I$160,"?*") -> 16 | E11: =IFERROR(AVERAGEIFS(楊梅20km名錄!$N$2:$N$160,楊梅20km名錄!$A$2:$A$160,$A11,楊梅20km名錄!$N$2:$N$160,">0"),"") -> 2.7058824 | F11: =IFERROR(AVERAGEIFS(楊梅20km名錄!$P$2:$P$160,楊梅20km名錄!$A$2:$A$160,$A11,楊梅20km名錄!$P$2:$P$160,">0"),"") -> 144.65412 | G11: =IFERROR(AVERAGEIFS(楊梅20km名錄!$R$2:$R$160,楊梅20km名錄!$A$2:$A$160,$A11,楊梅20km名錄!$R$2:$R$160,">0"),"") -> 3.0588235 | H11: =COUNTIFS(楊梅20km名錄!$A$2:$A$160,$A11,楊梅20km名錄!$M$2:$M$160,"大型") -> 0
A12: 10–15 km | B12: =COUNTIF(楊梅20km名錄!$A$2:$A$160,$A12) -> 62 | C12: =COUNTIFS(楊梅20km名錄!$A$2:$A$160,$A12,楊梅20km名錄!$D$2:$D$160,"<>") -> 45 | D12: =COUNTIFS(楊梅20km名錄!$A$2:$A$160,$A12,楊梅20km名錄!$I$2:$I$160,"?*") -> 44 | E12: =IFERROR(AVERAGEIFS(楊梅20km名錄!$N$2:$N$160,楊梅20km名錄!$A$2:$A$160,$A12,楊梅20km名錄!$N$2:$N$160,">0"),"") -> 4.0888889 | F12: =IFERROR(AVERAGEIFS(楊梅20km名錄!$P$2:$P$160,楊梅20km名錄!$A$2:$A$160,$A12,楊梅20km名錄!$P$2:$P$160,">0"),"") -> 234.81444 | G12: =IFERROR(AVERAGEIFS(楊梅20km名錄!$R$2:$R$160,楊梅20km名錄!$A$2:$A$160,$A12,楊梅20km名錄!$R$2:$R$160,">0"),"") -> 3.7555556 | H12: =COUNTIFS(楊梅20km名錄!$A$2:$A$160,$A12,楊梅20km名錄!$M$2:$M$160,"大型") -> 7
A13: 15–20 km | B13: =COUNTIF(楊梅20km名錄!$A$2:$A$160,$A13) -> 43 | C13: =COUNTIFS(楊梅20km名錄!$A$2:$A$160,$A13,楊梅20km名錄!$D$2:$D$160,"<>") -> 31 | D13: =COUNTIFS(楊梅20km名錄!$A$2:$A$160,$A13,楊梅20km名錄!$I$2:$I$160,"?*") -> 27 | E13: =IFERROR(AVERAGEIFS(楊梅20km名錄!$N$2:$N$160,楊梅20km名錄!$A$2:$A$160,$A13,楊梅20km名錄!$N$2:$N$160,">0"),"") -> 4.6129032 | F13: =IFERROR(AVERAGEIFS(楊梅20km名錄!$P$2:$P$160,楊梅20km名錄!$A$2:$A$160,$A13,楊梅20km名錄!$P$2:$P$160,">0"),"") -> 257.90419 | G13: =IFERROR(AVERAGEIFS(楊梅20km名錄!$R$2:$R$160,楊梅20km名錄!$A$2:$A$160,$A13,楊梅20km名錄!$R$2:$R$160,">0"),"") -> 6.2258065 | H13: =COUNTIFS(楊梅20km名錄!$A$2:$A$160,$A13,楊梅20km名錄!$M$2:$M$160,"大型") -> 5
A15: 楊梅 20 公里圈 — 依規模分級
A16: 規模 | B16: 家數 | C16: 平均教室數 | D16: 平均班舍面積(㎡) | E16: 平均師資(人) | F16: 平均核准班級數 | G16: 平均評分 | H16: 占比
A17: 大型 | B17: =COUNTIF(楊梅20km名錄!$M$2:$M$160,$A17) -> 16 | C17: =IFERROR(AVERAGEIFS(楊梅20km名錄!$N$2:$N$160,楊梅20km名錄!$M$2:$M$160,$A17),"") -> 7.4375 | D17: =IFERROR(AVERAGEIFS(楊梅20km名錄!$P$2:$P$160,楊梅20km名錄!$M$2:$M$160,$A17),"") -> 538.26688 | E17: =IFERROR(AVERAGEIFS(楊梅20km名錄!$R$2:$R$160,楊梅20km名錄!$M$2:$M$160,$A17),"") -> 8.8125 | F17: =IFERROR(AVERAGEIFS(楊梅20km名錄!$Q$2:$Q$160,楊梅20km名錄!$M$2:$M$160,$A17),"") -> 13.6 | G17: =IFERROR(AVERAGEIFS(楊梅20km名錄!$K$2:$K$160,楊梅20km名錄!$M$2:$M$160,$A17,楊梅20km名錄!$K$2:$K$160,">0"),"") -> 3.94 | H17: =IFERROR(B17/SUM($B$17:$B$19),"") -> 0.13333333
A18: 中型 | B18: =COUNTIF(楊梅20km名錄!$M$2:$M$160,$A18) -> 38 | C18: =IFERROR(AVERAGEIFS(楊梅20km名錄!$N$2:$N$160,楊梅20km名錄!$M$2:$M$160,$A18),"") -> 4.7105263 | D18: =IFERROR(AVERAGEIFS(楊梅20km名錄!$P$2:$P$160,楊梅20km名錄!$M$2:$M$160,$A18),"") -> 247.45789 | E18: =IFERROR(AVERAGEIFS(楊梅20km名錄!$R$2:$R$160,楊梅20km名錄!$M$2:$M$160,$A18),"") -> 4.6578947 | F18: =IFERROR(AVERAGEIFS(楊梅20km名錄!$Q$2:$Q$160,楊梅20km名錄!$M$2:$M$160,$A18),"") -> 12.026316 | G18: =IFERROR(AVERAGEIFS(楊梅20km名錄!$K$2:$K$160,楊梅20km名錄!$M$2:$M$160,$A18,楊梅20km名錄!$K$2:$K$160,">0"),"") -> 4.5606061 | H18: =IFERROR(B18/SUM($B$17:$B$19),"") -> 0.31666667
A19: 小型 | B19: =COUNTIF(楊梅20km名錄!$M$2:$M$160,$A19) -> 66 | C19: =IFERROR(AVERAGEIFS(楊梅20km名錄!$N$2:$N$160,楊梅20km名錄!$M$2:$M$160,$A19),"") -> 2.6969697 | D19: =IFERROR(AVERAGEIFS(楊梅20km名錄!$P$2:$P$160,楊梅20km名錄!$M$2:$M$160,$A19),"") -> 131.05818 | E19: =IFERROR(AVERAGEIFS(楊梅20km名錄!$R$2:$R$160,楊梅20km名錄!$M$2:$M$160,$A19),"") -> 3.2121212 | F19: =IFERROR(AVERAGEIFS(楊梅20km名錄!$Q$2:$Q$160,楊梅20km名錄!$M$2:$M$160,$A19),"") -> 7.0454545 | G19: =IFERROR(AVERAGEIFS(楊梅20km名錄!$K$2:$K$160,楊梅20km名錄!$M$2:$M$160,$A19,楊梅20km名錄!$K$2:$K$160,">0"),"") -> 4.6017241 | H19: =IFERROR(B19/SUM($B$17:$B$19),"") -> 0.55
A21: 楊梅 20 公里圈 — 依行政區
A22: 行政區 | B22: 家數 | C22: 有立案資料 | D22: 有 Email | E22: 平均教室數 | F22: 平均班舍面積(㎡) | G22: 平均師資(人) | H22: 大型
A23: 楊梅區 | B23: =COUNTIF(楊梅20km名錄!$F$2:$F$160,$A23) -> 19 | C23: =COUNTIFS(楊梅20km名錄!$F$2:$F$160,$A23,楊梅20km名錄!$D$2:$D$160,"<>") -> 14 | D23: =COUNTIFS(楊梅20km名錄!$F$2:$F$160,$A23,楊梅20km名錄!$I$2:$I$160,"?*") -> 13 | E23: =IFERROR(AVERAGEIFS(楊梅20km名錄!$N$2:$N$160,楊梅20km名錄!$F$2:$F$160,$A23,楊梅20km名錄!$N$2:$N$160,">0"),"") -> 3.3571429 | F23: =IFERROR(AVERAGEIFS(楊梅20km名錄!$P$2:$P$160,楊梅20km名錄!$F$2:$F$160,$A23,楊梅20km名錄!$P$2:$P$160,">0"),"") -> 156.975 | G23: =IFERROR(AVERAGEIFS(楊梅20km名錄!$R$2:$R$160,楊梅20km名錄!$F$2:$F$160,$A23,楊梅20km名錄!$R$2:$R$160,">0"),"") -> 4.8571429 | H23: =COUNTIFS(楊梅20km名錄!$F$2:$F$160,$A23,楊梅20km名錄!$M$2:$M$160,"大型") -> 0
A24: 平鎮區 | B24: =COUNTIF(楊梅20km名錄!$F$2:$F$160,$A24) -> 14 | C24: =COUNTIFS(楊梅20km名錄!$F$2:$F$160,$A24,楊梅20km名錄!$D$2:$D$160,"<>") -> 13 | D24: =COUNTIFS(楊梅20km名錄!$F$2:$F$160,$A24,楊梅20km名錄!$I$2:$I$160,"?*") -> 13 | E24: =IFERROR(AVERAGEIFS(楊梅20km名錄!$N$2:$N$160,楊梅20km名錄!$F$2:$F$160,$A24,楊梅20km名錄!$N$2:$N$160,">0"),"") -> 4 | F24: =IFERROR(AVERAGEIFS(楊梅20km名錄!$P$2:$P$160,楊梅20km名錄!$F$2:$F$160,$A24,楊梅20km名錄!$P$2:$P$160,">0"),"") -> 197.83 | G24: =IFERROR(AVERAGEIFS(楊梅20km名錄!$R$2:$R$160,楊梅20km名錄!$F$2:$F$160,$A24,楊梅20km名錄!$R$2:$R$160,">0"),"") -> 3.9230769 | H24: =COUNTIFS(楊梅20km名錄!$F$2:$F$160,$A24,楊梅20km名錄!$M$2:$M$160,"大型") -> 2
A25: 大園區 | B25: =COUNTIF(楊梅20km名錄!$F$2:$F$160,$A25) -> 14 | C25: =COUNTIFS(楊梅20km名錄!$F$2:$F$160,$A25,楊梅20km名錄!$D$2:$D$160,"<>") -> 12 | D25: =COUNTIFS(楊梅20km名錄!$F$2:$F$160,$A25,楊梅20km名錄!$I$2:$I$160,"?*") -> 12 | E25: =IFERROR(AVERAGEIFS(楊梅20km名錄!$N$2:$N$160,楊梅20km名錄!$F$2:$F$160,$A25,楊梅20km名錄!$N$2:$N$160,">0"),"") -> 4.8333333 | F25: =IFERROR(AVERAGEIFS(楊梅20km名錄!$P$2:$P$160,楊梅20km名錄!$F$2:$F$160,$A25,楊梅20km名錄!$P$2:$P$160,">0"),"") -> 274.3625 | G25: =IFERROR(AVERAGEIFS(楊梅20km名錄!$R$2:$R$160,楊梅20km名錄!$F$2:$F$160,$A25,楊梅20km名錄!$R$2:$R$160,">0"),"") -> 4.5833333 | H25: =COUNTIFS(楊梅20km名錄!$F$2:$F$160,$A25,楊梅20km名錄!$M$2:$M$160,"大型") -> 3
A26: 龍潭區 | B26: =COUNTIF(楊梅20km名錄!$F$2:$F$160,$A26) -> 12 | C26: =COUNTIFS(楊梅20km名錄!$F$2:$F$160,$A26,楊梅20km名錄!$D$2:$D$160,"<>") -> 8 | D26: =COUNTIFS(楊梅20km名錄!$F$2:$F$160,$A26,楊梅20km名錄!$I$2:$I$160,"?*") -> 7 | E26: =IFERROR(AVERAGEIFS(楊梅20km名錄!$N$2:$N$160,楊梅20km名錄!$F$2:$F$160,$A26,楊梅20km名錄!$N$2:$N$160,">0"),"") -> 3.375 | F26: =IFERROR(AVERAGEIFS(楊梅20km名錄!$P$2:$P$160,楊梅20km名錄!$F$2:$F$160,$A26,楊梅20km名錄!$P$2:$P$160,">0"),"") -> 266.765 | G26: =IFERROR(AVERAGEIFS(楊梅20km名錄!$R$2:$R$160,楊梅20km名錄!$F$2:$F$160,$A26,楊梅20km名錄!$R$2:$R$160,">0"),"") -> 1.5 | H26: =COUNTIFS(楊梅20km名錄!$F$2:$F$160,$A26,楊梅20km名錄!$M$2:$M$160,"大型") -> 2
A27: 觀音區 | B27: =COUNTIF(楊梅20km名錄!$F$2:$F$160,$A27) -> 11 | C27: =COUNTIFS(楊梅20km名錄!$F$2:$F$160,$A27,楊梅20km名錄!$D$2:$D$160,"<>") -> 8 | D27: =COUNTIFS(楊梅20km名錄!$F$2:$F$160,$A27,楊梅20km名錄!$I$2:$I$160,"?*") -> 8 | E27: =IFERROR(AVERAGEIFS(楊梅20km名錄!$N$2:$N$160,楊梅20km名錄!$F$2:$F$160,$A27,楊梅20km名錄!$N$2:$N$160,">0"),"") -> 3.875 | F27: =IFERROR(AVERAGEIFS(楊梅20km名錄!$P$2:$P$160,楊梅20km名錄!$F$2:$F$160,$A27,楊梅20km名錄!$P$2:$P$160,">0"),"") -> 205.4325 | G27: =IFERROR(AVERAGEIFS(楊梅20km名錄!$R$2:$R$160,楊梅20km名錄!$F$2:$F$160,$A27,楊梅20km名錄!$R$2:$R$160,">0"),"") -> 3 | H27: =COUNTIFS(楊梅20km名錄!$F$2:$F$160,$A27,楊梅20km名錄!$M$2:$M$160,"大型") -> 0
A28: 桃園區 | B28: =COUNTIF(楊梅20km名錄!$F$2:$F$160,$A28) -> 11 | C28: =COUNTIFS(楊梅20km名錄!$F$2:$F$160,$A28,楊梅20km名錄!$D$2:$D$160,"<>") -> 8 | D28: =COUNTIFS(楊梅20km名錄!$F$2:$F$160,$A28,楊梅20km名錄!$I$2:$I$160,"?*") -> 8 | E28: =IFERROR(AVERAGEIFS(楊梅20km名錄!$N$2:$N$160,楊梅20km名錄!$F$2:$F$160,$A28,楊梅20km名錄!$N$2:$N$160,">0"),"") -> 3.75 | F28: =IFERROR(AVERAGEIFS(楊梅20km名錄!$P$2:$P$160,楊梅20km名錄!$F$2:$F$160,$A28,楊梅20km名錄!$P$2:$P$160,">0"),"") -> 193.26875 | G28: =IFERROR(AVERAGEIFS(楊梅20km名錄!$R$2:$R$160,楊梅20km名錄!$F$2:$F$160,$A28,楊梅20km名錄!$R$2:$R$160,">0"),"") -> 3.375 | H28: =COUNTIFS(楊梅20km名錄!$F$2:$F$160,$A28,楊梅20km名錄!$M$2:$M$160,"大型") -> 0
A29: 中壢區 | B29: =COUNTIF(楊梅20km名錄!$F$2:$F$160,$A29) -> 10 | C29: =COUNTIFS(楊梅20km名錄!$F$2:$F$160,$A29,楊梅20km名錄!$D$2:$D$160,"<>") -> 8 | D29: =COUNTIFS(楊梅20km名錄!$F$2:$F$160,$A29,楊梅20km名錄!$I$2:$I$160,"?*") -> 8 | E29: =IFERROR(AVERAGEIFS(楊梅20km名錄!$N$2:$N$160,楊梅20km名錄!$F$2:$F$160,$A29,楊梅20km名錄!$N$2:$N$160,">0"),"") -> 3 | F29: =IFERROR(AVERAGEIFS(楊梅20km名錄!$P$2:$P$160,楊梅20km名錄!$F$2:$F$160,$A29,楊梅20km名錄!$P$2:$P$160,">0"),"") -> 164.34125 | G29: =IFERROR(AVERAGEIFS(楊梅20km名錄!$R$2:$R$160,楊梅20km名錄!$F$2:$F$160,$A29,楊梅20km名錄!$R$2:$R$160,">0"),"") -> 4.75 | H29: =COUNTIFS(楊梅20km名錄!$F$2:$F$160,$A29,楊梅20km名錄!$M$2:$M$160,"大型") -> 0
A30: 大溪區 | B30: =COUNTIF(楊梅20km名錄!$F$2:$F$160,$A30) -> 10 | C30: =COUNTIFS(楊梅20km名錄!$F$2:$F$160,$A30,楊梅20km名錄!$D$2:$D$160,"<>") -> 7 | D30: =COUNTIFS(楊梅20km名錄!$F$2:$F$160,$A30,楊梅20km名錄!$I$2:$I$160,"?*") -> 7 | E30: =IFERROR(AVERAGEIFS(楊梅20km名錄!$N$2:$N$160,楊梅20km名錄!$F$2:$F$160,$A30,楊梅20km名錄!$N$2:$N$160,">0"),"") -> 2.8571429 | F30: =IFERROR(AVERAGEIFS(楊梅20km名錄!$P$2:$P$160,楊梅20km名錄!$F$2:$F$160,$A30,楊梅20km名錄!$P$2:$P$160,">0"),"") -> 246.05571 | G30: =IFERROR(AVERAGEIFS(楊梅20km名錄!$R$2:$R$160,楊梅20km名錄!$F$2:$F$160,$A30,楊梅20km名錄!$R$2:$R$160,">0"),"") -> 2.8571429 | H30: =COUNTIFS(楊梅20km名錄!$F$2:$F$160,$A30,楊梅20km名錄!$M$2:$M$160,"大型") -> 1
A31: 八德區 | B31: =COUNTIF(楊梅20km名錄!$F$2:$F$160,$A31) -> 10 | C31: =COUNTIFS(楊梅20km名錄!$F$2:$F$160,$A31,楊梅20km名錄!$D$2:$D$160,"<>") -> 8 | D31: =COUNTIFS(楊梅20km名錄!$F$2:$F$160,$A31,楊梅20km名錄!$I$2:$I$160,"?*") -> 8 | E31: =IFERROR(AVERAGEIFS(楊梅20km名錄!$N$2:$N$160,楊梅20km名錄!$F$2:$F$160,$A31,楊梅20km名錄!$N$2:$N$160,">0"),"") -> 3.875 | F31: =IFERROR(AVERAGEIFS(楊梅20km名錄!$P$2:$P$160,楊梅20km名錄!$F$2:$F$160,$A31,楊梅20km名錄!$P$2:$P$160,">0"),"") -> 233.01375 | G31: =IFERROR(AVERAGEIFS(楊梅20km名錄!$R$2:$R$160,楊梅20km名錄!$F$2:$F$160,$A31,楊梅20km名錄!$R$2:$R$160,">0"),"") -> 2.625 | H31: =COUNTIFS(楊梅20km名錄!$F$2:$F$160,$A31,楊梅20km名錄!$M$2:$M$160,"大型") -> 2
A32: 鶯歌區 | B32: =COUNTIF(楊梅20km名錄!$F$2:$F$160,$A32) -> 10 | C32: =COUNTIFS(楊梅20km名錄!$F$2:$F$160,$A32,楊梅20km名錄!$D$2:$D$160,"<>") -> 9 | D32: =COUNTIFS(楊梅20km名錄!$F$2:$F$160,$A32,楊梅20km名錄!$I$2:$I$160,"?*") -> 6 | E32: =IFERROR(AVERAGEIFS(楊梅20km名錄!$N$2:$N$160,楊梅20km名錄!$F$2:$F$160,$A32,楊梅20km名錄!$N$2:$N$160,">0"),"") -> 4.3333333 | F32: =IFERROR(AVERAGEIFS(楊梅20km名錄!$P$2:$P$160,楊梅20km名錄!$F$2:$F$160,$A32,楊梅20km名錄!$P$2:$P$160,">0"),"") -> 261.59667 | G32: =IFERROR(AVERAGEIFS(楊梅20km名錄!$R$2:$R$160,楊梅20km名錄!$F$2:$F$160,$A32,楊梅20km名錄!$R$2:$R$160,">0"),"") -> 6.4444444 | H32: =COUNTIFS(楊梅20km名錄!$F$2:$F$160,$A32,楊梅20km名錄!$M$2:$M$160,"大型") -> 2
A33: 蘆竹區 | B33: =COUNTIF(楊梅20km名錄!$F$2:$F$160,$A33) -> 7 | C33: =COUNTIFS(楊梅20km名錄!$F$2:$F$160,$A33,楊梅20km名錄!$D$2:$D$160,"<>") -> 4 | D33: =COUNTIFS(楊梅20km名錄!$F$2:$F$160,$A33,楊梅20km名錄!$I$2:$I$160,"?*") -> 4 | E33: =IFERROR(AVERAGEIFS(楊梅20km名錄!$N$2:$N$160,楊梅20km名錄!$F$2:$F$160,$A33,楊梅20km名錄!$N$2:$N$160,">0"),"") -> 5.25 | F33: =IFERROR(AVERAGEIFS(楊梅20km名錄!$P$2:$P$160,楊梅20km名錄!$F$2:$F$160,$A33,楊梅20km名錄!$P$2:$P$160,">0"),"") -> 203.045 | G33: =IFERROR(AVERAGEIFS(楊梅20km名錄!$R$2:$R$160,楊梅20km名錄!$F$2:$F$160,$A33,楊梅20km名錄!$R$2:$R$160,">0"),"") -> 8 | H33: =COUNTIFS(楊梅20km名錄!$F$2:$F$160,$A33,楊梅20km名錄!$M$2:$M$160,"大型") -> 1
A34: 湖口鄉 | B34: =COUNTIF(楊梅20km名錄!$F$2:$F$160,$A34) -> 7 | C34: =COUNTIFS(楊梅20km名錄!$F$2:$F$160,$A34,楊梅20km名錄!$D$2:$D$160,"<>") -> 5 | D34: =COUNTIFS(楊梅20km名錄!$F$2:$F$160,$A34,楊梅20km名錄!$I$2:$I$160,"?*") -> 4 | E34: =IFERROR(AVERAGEIFS(楊梅20km名錄!$N$2:$N$160,楊梅20km名錄!$F$2:$F$160,$A34,楊梅20km名錄!$N$2:$N$160,">0"),"") -> 4.2 | F34: =IFERROR(AVERAGEIFS(楊梅20km名錄!$P$2:$P$160,楊梅20km名錄!$F$2:$F$160,$A34,楊梅20km名錄!$P$2:$P$160,">0"),"") -> 224.938 | G34: =IFERROR(AVERAGEIFS(楊梅20km名錄!$R$2:$R$160,楊梅20km名錄!$F$2:$F$160,$A34,楊梅20km名錄!$R$2:$R$160,">0"),"") -> 4.6 | H34: =COUNTIFS(楊梅20km名錄!$F$2:$F$160,$A34,楊梅20km名錄!$M$2:$M$160,"大型") -> 1
... A42: 龜山區 | B42: =COUNTIF(楊梅20km名錄!$F$2:$F$160,$A42) -> 1 | C42: =COUNTIFS(楊梅20km名錄!$F$2:$F$160,$A42,楊梅20km名錄!$D$2:$D$160,"<>") -> 1 | D42: =COUNTIFS(楊梅20km名錄!$F$2:$F$160,$A42,楊梅20km名錄!$I$2:$I$160,"?*") -> 1 | E42: =IFERROR(AVERAGEIFS(楊梅20km名錄!$N$2:$N$160,楊梅20km名錄!$F$2:$F$160,$A42,楊梅20km名錄!$N$2:$N$160,">0"),"") -> 3 | F42: =IFERROR(AVERAGEIFS(楊梅20km名錄!$P$2:$P$160,楊梅20km名錄!$F$2:$F$160,$A42,楊梅20km名錄!$P$2:$P$160,">0"),"") -> 157.44 | G42: =IFERROR(AVERAGEIFS(楊梅20km名錄!$R$2:$R$160,楊梅20km名錄!$F$2:$F$160,$A42,楊梅20km名錄!$R$2:$R$160,">0"),"") -> 2 | H42: =COUNTIFS(楊梅20km名錄!$F$2:$F$160,$A42,楊梅20km名錄!$M$2:$M$160,"大型") -> 0
A44: 全台英文補習班 — 依縣市
A45: 縣市 | B45: 家數 | C45: 有 Email | D45: 平均教室數 | E45: 平均班舍面積(㎡) | F45: 平均師資(人) | G45: 大型 | H45: 小型
A46: 桃園市 | B46: =COUNTIF(全台英文補習班!$A$2:$A$4686,$A46) -> 925 | C46: =COUNTIFS(全台英文補習班!$A$2:$A$4686,$A46,全台英文補習班!$F$2:$F$4686,"?*") -> 885 | D46: =IFERROR(AVERAGEIFS(全台英文補習班!$H$2:$H$4686,全台英文補習班!$A$2:$A$4686,$A46,全台英文補習班!$H$2:$H$4686,">0"),"") -> 3.8410811 | E46: =IFERROR(AVERAGEIFS(全台英文補習班!$J$2:$J$4686,全台英文補習班!$A$2:$A$4686,$A46,全台英文補習班!$J$2:$J$4686,">0"),"") -> 213.04564 | F46: =IFERROR(AVERAGEIFS(全台英文補習班!$L$2:$L$4686,全台英文補習班!$A$2:$A$4686,$A46,全台英文補習班!$L$2:$L$4686,">0"),"") -> 4.6706915 | G46: =COUNTIFS(全台英文補習班!$A$2:$A$4686,$A46,全台英文補習班!$G$2:$G$4686,"大型") -> 110 | H46: =COUNTIFS(全台英文補習班!$A$2:$A$4686,$A46,全台英文補習班!$G$2:$G$4686,"小型") -> 539
A47: 新北市 | B47: =COUNTIF(全台英文補習班!$A$2:$A$4686,$A47) -> 890 | C47: =COUNTIFS(全台英文補習班!$A$2:$A$4686,$A47,全台英文補習班!$F$2:$F$4686,"?*") -> 496 | D47: =IFERROR(AVERAGEIFS(全台英文補習班!$H$2:$H$4686,全台英文補習班!$A$2:$A$4686,$A47,全台英文補習班!$H$2:$H$4686,">0"),"") -> 4.1460674 | E47: =IFERROR(AVERAGEIFS(全台英文補習班!$J$2:$J$4686,全台英文補習班!$A$2:$A$4686,$A47,全台英文補習班!$J$2:$J$4686,">0"),"") -> 205.49864 | F47: =IFERROR(AVERAGEIFS(全台英文補習班!$L$2:$L$4686,全台英文補習班!$A$2:$A$4686,$A47,全台英文補習班!$L$2:$L$4686,">0"),"") -> 7.0406977 | G47: =COUNTIFS(全台英文補習班!$A$2:$A$4686,$A47,全台英文補習班!$G$2:$G$4686,"大型") -> 120 | H47: =COUNTIFS(全台英文補習班!$A$2:$A$4686,$A47,全台英文補習班!$G$2:$G$4686,"小型") -> 524
A48: 臺北市 | B48: =COUNTIF(全台英文補習班!$A$2:$A$4686,$A48) -> 531 | C48: =COUNTIFS(全台英文補習班!$A$2:$A$4686,$A48,全台英文補習班!$F$2:$F$4686,"?*") -> 508 | D48: =IFERROR(AVERAGEIFS(全台英文補習班!$H$2:$H$4686,全台英文補習班!$A$2:$A$4686,$A48,全台英文補習班!$H$2:$H$4686,">0"),"") -> 4.3615819 | E48: =IFERROR(AVERAGEIFS(全台英文補習班!$J$2:$J$4686,全台英文補習班!$A$2:$A$4686,$A48,全台英文補習班!$J$2:$J$4686,">0"),"") -> 174.12074 | F48: =IFERROR(AVERAGEIFS(全台英文補習班!$L$2:$L$4686,全台英文補習班!$A$2:$A$4686,$A48,全台英文補習班!$L$2:$L$4686,">0"),"") -> 14.351044 | G48: =COUNTIFS(全台英文補習班!$A$2:$A$4686,$A48,全台英文補習班!$G$2:$G$4686,"大型") -> 50 | H48: =COUNTIFS(全台英文補習班!$A$2:$A$4686,$A48,全台英文補習班!$G$2:$G$4686,"小型") -> 355
A49: 臺中市 | B49: =COUNTIF(全台英文補習班!$A$2:$A$4686,$A49) -> 493 | C49: =COUNTIFS(全台英文補習班!$A$2:$A$4686,$A49,全台英文補習班!$F$2:$F$4686,"?*") -> 341 | D49: =IFERROR(AVERAGEIFS(全台英文補習班!$H$2:$H$4686,全台英文補習班!$A$2:$A$4686,$A49,全台英文補習班!$H$2:$H$4686,">0"),"") -> 4.4482759 | E49: =IFERROR(AVERAGEIFS(全台英文補習班!$J$2:$J$4686,全台英文補習班!$A$2:$A$4686,$A49,全台英文補習班!$J$2:$J$4686,">0"),"") -> 282.28759 | F49: =IFERROR(AVERAGEIFS(全台英文補習班!$L$2:$L$4686,全台英文補習班!$A$2:$A$4686,$A49,全台英文補習班!$L$2:$L$4686,">0"),"") -> 5.777027 | G49: =COUNTIFS(全台英文補習班!$A$2:$A$4686,$A49,全台英文補習班!$G$2:$G$4686,"大型") -> 103 | H49: =COUNTIFS(全台英文補習班!$A$2:$A$4686,$A49,全台英文補習班!$G$2:$G$4686,"小型") -> 249
A50: 彰化縣 | B50: =COUNTIF(全台英文補習班!$A$2:$A$4686,$A50) -> 291 | C50: =COUNTIFS(全台英文補習班!$A$2:$A$4686,$A50,全台英文補習班!$F$2:$F$4686,"?*") -> 223 | D50: =IFERROR(AVERAGEIFS(全台英文補習班!$H$2:$H$4686,全台英文補習班!$A$2:$A$4686,$A50,全台英文補習班!$H$2:$H$4686,">0"),"") -> 2.4931034 | E50: =IFERROR(AVERAGEIFS(全台英文補習班!$J$2:$J$4686,全台英文補習班!$A$2:$A$4686,$A50,全台英文補習班!$J$2:$J$4686,">0"),"") -> 146.0195 | F50: =IFERROR(AVERAGEIFS(全台英文補習班!$L$2:$L$4686,全台英文補習班!$A$2:$A$4686,$A50,全台英文補習班!$L$2:$L$4686,">0"),"") -> 3.2229965 | G50: =COUNTIFS(全台英文補習班!$A$2:$A$4686,$A50,全台英文補習班!$G$2:$G$4686,"大型") -> 12 | H50: =COUNTIFS(全台英文補習班!$A$2:$A$4686,$A50,全台英文補習班!$G$2:$G$4686,"小型") -> 248
A51: 高雄市 | B51: =COUNTIF(全台英文補習班!$A$2:$A$4686,$A51) -> 277 | C51: =COUNTIFS(全台英文補習班!$A$2:$A$4686,$A51,全台英文補習班!$F$2:$F$4686,"?*") -> 265 | D51: =IFERROR(AVERAGEIFS(全台英文補習班!$H$2:$H$4686,全台英文補習班!$A$2:$A$4686,$A51,全台英文補習班!$H$2:$H$4686,">0"),"") -> 4.3465704 | E51: =IFERROR(AVERAGEIFS(全台英文補習班!$J$2:$J$4686,全台英文補習班!$A$2:$A$4686,$A51,全台英文補習班!$J$2:$J$4686,">0"),"") -> 239.41986 | F51: =IFERROR(AVERAGEIFS(全台英文補習班!$L$2:$L$4686,全台英文補習班!$A$2:$A$4686,$A51,全台英文補習班!$L$2:$L$4686,">0"),"") -> 6.5416667 | G51: =COUNTIFS(全台英文補習班!$A$2:$A$4686,$A51,全台英文補習班!$G$2:$G$4686,"大型") -> 49 | H51: =COUNTIFS(全台英文補習班!$A$2:$A$4686,$A51,全台英文補習班!$G$2:$G$4686,"小型") -> 143
A52: 臺南市 | B52: =COUNTIF(全台英文補習班!$A$2:$A$4686,$A52) -> 259 | C52: =COUNTIFS(全台英文補習班!$A$2:$A$4686,$A52,全台英文補習班!$F$2:$F$4686,"?*") -> 207 | D52: =IFERROR(AVERAGEIFS(全台英文補習班!$H$2:$H$4686,全台英文補習班!$A$2:$A$4686,$A52,全台英文補習班!$H$2:$H$4686,">0"),"") -> 3.1042471 | E52: =IFERROR(AVERAGEIFS(全台英文補習班!$J$2:$J$4686,全台英文補習班!$A$2:$A$4686,$A52,全台英文補習班!$J$2:$J$4686,">0"),"") -> 179.69197 | F52: =IFERROR(AVERAGEIFS(全台英文補習班!$L$2:$L$4686,全台英文補習班!$A$2:$A$4686,$A52,全台英文補習班!$L$2:$L$4686,">0"),"") -> 4.2093023 | G52: =COUNTIFS(全台英文補習班!$A$2:$A$4686,$A52,全台英文補習班!$G$2:$G$4686,"大型") -> 24 | H52: =COUNTIFS(全台英文補習班!$A$2:$A$4686,$A52,全台英文補習班!$G$2:$G$4686,"小型") -> 189
...

Sheet 未對上立案
A1: 距離(km) | B1: 名稱 | C1: 行政區 | D1: 地址 | E1: 電話 | F1: 評分 | G1: 評論數 | H1: Google Maps
A2: 0.89 | B2: 空中美語兒童美語 楊梅艾奇德 分校 | C2: 楊梅區 | D2: 桃園市楊梅區四維里文化街96號 | E2: 03 481 8811 | F2: 5 | G2: 1 | H2: 地圖
A3: 3.03 | B3: 甜蜜美語文理短期補習班 | C3: 楊梅區 | D3: 桃園市楊梅區裕成里裕成路158巷31號 | E3: 03 431 4018 | F3: 3 | G3: 2 | H3: 地圖
A4: 4.35 | B4: 佑育語文文理短期補習班 | C4: 楊梅區 | D4: 桃園市楊梅區新榮里富榮路15號2樓 | E4: 03 490 6733 | F4: 5 | G4: 2 | H4: 地圖
A5: 4.57 | B5: 明子園幼兒園/課後班/安親班/文化國小安親/美語安親/ | C5: 平鎮區 | D5: 桃園市平鎮區復旦里文化街68巷6號 | E5: 03 494 5172 | F5: 4.4 | G5: 58 | H5: 地圖
A6: 5.51 | B6: 喬登美語(潛龍分校) | C6: 龍潭區 | D6: 桃園市龍潭區烏樹林里中豐路418之1號 | H6: 地圖
A7: 7.6 | B7: 吉的堡美語學校(中壢大崙分校) | C7: 中壢區 | D7: 桃園市中壢區內厝里中正路四段70號 | E7: 03 498 6090 | F7: 4.5 | G7: 8 | H7: 地圖
A8: 7.65 | B8: 挪亞美語作文短期補習班 | C8: 龍潭區 | D8: 桃園市龍潭區武漢里國聯街21號 | E8: 03 499 6048 | H8: 地圖
A9: 8.52 | B9: 王莉美語安親中心 | C9: 楊梅區 | D9: 桃園市楊梅區 | F9: 3.8 | G9: 4 | H9: 地圖
A10: 8.93 | B10: 科林外語 | C10: 中壢區 | D10: 桃園市中壢區華愛里榮民南路83號 | H10: 地圖
A11: 9.45 | B11: 維吉尼亞文理語文短期補習班 | C11: 楊梅區 | D11: 桃園市楊梅區豐野里民富路三段924巷7號 | E11: 03 472 7887 | H11: 地圖
A12: 10.06 | B12: 茗雅文理美語短期補習班 | C12: 大溪區 | D12: 桃園市大溪區光明里三元一街31號 | E12: 03 389 2327 | H12: 地圖
A13: 10.55 | B13: 日進文理語文短期補習班 | C13: 龍潭區 | D13: 桃園市龍潭區建林里民族路216巷16弄3號 | E13: 03 470 4629 | H13: 地圖
A14: 10.79 | B14: 競升文理美語短期補習班 | C14: 龍潭區 | D14: 桃園市龍潭區三林里民族路293巷16弄5號 | E14: 03 499 3535 | H14: 地圖
A15: 11.47 | B15: 大英美語文理補習班 | C15: 觀音區 | D15: 桃園市觀音區新坡里文中路66號 | E15: 03 498 7622 | F15: 5 | G15: 1 | H15: 地圖
A16: 11.49 | B16: 語捷語文短期補習班 | C16: 觀音區 | D16: 桃園市觀音區新坡里中山路二段470號 | E16: 03 498 6819 | F16: 5 | G16: 1 | H16: 地圖
A17: 11.69 | B17: 私立成龍語文短期補習班 | C17: 大溪區 | D17: 桃園市大溪區福仁里登龍路20巷2號1樓 | E17: 03 387 9867 | H17: 地圖
A18: 12.29 | B18: 學子語文文理短期補習班 | C18: 大溪區 | D18: 桃園市大溪區一心里文化路161號 | E18: 03 387 3139 | H18: 地圖
A19: 12.45 | B19: 喬登美語 | C19: 蘆竹區 | D19: 桃園市蘆竹區新興里文中路一段19巷36號 | E19: 080 003 7789 | F19: 3 | G19: 2 | H19: 地圖
A20: 12.58 | B20: 私立兒童星球美語短期補習班 | C20: 桃園區 | D20: 桃園市桃園區龍安里國豐十街258號 | E20: 03 360 0292 | F20: 4.3 | G20: 6 | H20: 地圖
A21: 12.59 | B21: 夏恩英語 桃園大成校 | C21: 八德區 | D21: 桃園市八德區大和里建國路1110號 | E21: 03 363 7598 | F21: 5 | G21: 8 | H21: 地圖
A22: 12.65 | B22: 承信短期美語補習班 | C22: 八德區 | D22: 桃園市八德區 | H22: 地圖
A23: 13.23 | B23: 冠昱補習班 （湖口國高中補習班）《國中全科班》1對1家教班｜全民英檢班｜私中衝刺班 | C23: 湖口鄉 | D23: 新竹縣湖口鄉中正村中正路二段340號 | E23: 03 599 1431 | F23: 4 | G23: 86 | H23: 地圖
A24: 14.04 | B24: 薪傳巨人升學文理補習班&Live互動美語湖口信勢分校 | C24: 湖口鄉 | D24: 新竹縣湖口鄉中正村中山路一段588號 | E24: 03 590 6111 | F24: 4.2 | G24: 19 | H24: 地圖
A25: 14.12 | B25: MPM數學 常春藤英語 新埔分校 | C25: 新埔鎮 | D25: 新竹縣新埔鎮四座里中正路192號 | E25: 03 589 7903 | F25: 4.4 | G25: 13 | H25: 地圖
A26: 14.23 | B26: 佳仁美語才藝短期補習班 | C26: 關西鎮 | D26: 新竹縣關西鎮北斗里中興路12號 | E26: 03 587 8600 | F26: 5 | G26: 3 | H26: 地圖
A27: 14.33 | B27: 玉兔兒童課後照顧服務中心《新莊國小 大竹國小 大華國小》蘆竹安親班 蘆竹才藝班 蘆竹兒童美語 蘆竹兒童舞蹈 蘆竹暑期班 | C27: 蘆竹區 | D27: 桃園市蘆竹區大竹里南竹路五段222號 | E27: 03 323 2446 | F27: 5 | G27: 41 | H27: 地圖
A28: 14.49 | B28: 賴世雄美語 傅老師補習班 | C28: 新埔鎮 | D28: 新竹縣新埔鎮 | H28: 地圖
A29: 15.48 | B29: 漢林美語短期補習班 | C29: 大園區 | D29: 桃園市大園區埔心里埔心街99-5號 | E29: 03 381 3036 | H29: 地圖
A30: 16 | B30: 惠翔語文短期補習班 | C30: 大園區 | D30: 桃園市大園區田心里華興路50號 | E30: 03 385 9622 | F30: 4 | G30: 4 | H30: 地圖
A31: 16.06 | B31: 雷克斯美語短期補習班 | C31: 觀音區 | D31: 桃園市觀音區觀音里中正路257號 | E31: 03 473 5266 | F31: 5 | G31: 1 | H31: 地圖
A32: 16.42 | B32: 私立米可美語短期補習班 | C32: 桃園區 | D32: 桃園市桃園區成功里桃三街62號1樓 | E32: 03 347 3366 | H32: 地圖
A33: 16.91 | B33: 私立葵思美語短期補習班 | C33: 桃園區 | D33: 桃園區莊敬里莊敬路一段210巷59號 | E33: 03 317 3712 | H33: 地圖
A34: 17.47 | B34: 學詮珠心算語文短期補習班 | C34: 鶯歌區 | D34: 新北市鶯歌區南鶯里育才街90號 | E34: 02 2678 6728 | H34: 地圖
A35: 17.56 | B35: 長頸鹿美語-南崁光明分校 (宇成)安親/美語/英檢/國中/國一先修/升學/私校專班 | C35: 蘆竹區 | D35: 桃園市蘆竹區福昌里南昌路264號1樓 | E35: 03 312 2000 | F35: 3.7 | G35: 3 | H35: 地圖
A36: 18.95 | B36: 文強文理語文短期補習班 | C36: 三峽區 | D36: 新北市三峽區中埔里弘園街36巷8號 | E36: 02 8671 1066 | F36: 5 | G36: 1 | H36: 地圖
A37: 19.06 | B37: 徐薇英文芎林文林分校-文林文理才藝補習班 | C37: 芎林鄉 | D37: 新竹縣芎林鄉文林村文德路30號1樓 | E37: 03 592 1000 | F37: 4.8 | G37: 63 | H37: 地圖
A38: 19.86 | B38: 樂獅英語竹北興隆分校 國小國中高中英文補習班・自然發音・全民英檢 竹北英文補習班推薦 | C38: 竹北市 | D38: 新竹縣竹北市鹿場里文興路195號 | E38: 03 550 0887 | F38: 5 | G38: 302 | H38: 地圖
A39: 19.92 | B39: 金蘋果語言中心-竹北教室 | C39: 竹北市 | D39: 新竹縣竹北市鹿場里成功十五街 | E39: 0956 521 333 | H39: 地圖
A40: 19.93 | B40: 私立汶喬語文短期補習班 | C40: 三峽區 | D40: 新北市三峽區中正里大同路88巷6號 | E40: 02 2674 2314 | F40: 4 | G40: 1 | H40: 地圖
...
